<mujoco model="legs">
    <compiler angle="degree" coordinate="global" />
    <default>
        <joint stiffness="5" damping="5"/>
    </default>
    <worldbody>
        <body name="base">
            <joint armature="0" axis="1 0 0" damping="0" limited="false" name="ignorex" pos="0 0 0" stiffness="0" type="slide"/>
            <joint armature="0" axis="0 0 1" damping="0" limited="false" name="ignorez" pos="0 0 0" stiffness="0" type="slide"/>
            <joint armature="0" axis="0 1 0" damping="0" limited="false" name="ignorey" pos="0 0 0" stiffness="0" type="hinge"/>
            <geom name="base" size="0.1 0.2 0.4" type="box" mass="15"/>

            <!-- Beginning of right leg -->
            <body name="right_hip">
                <geom name="right_hip_geom" size="0.1" type="sphere" pos="0 -0.15 -0.4" mass="0.5"/>
                <body name="right_thigh">
                    <joint axis="0 1 0" name="right_hip_to_right_thigh" pos="0 -0.15 -0.4" limited="true" range="-90 90" type="hinge"/>
                    <geom name="right_thigh_geom" fromto="0 -0.15 -0.5 0 -0.15 -0.8" size="0.05" type="capsule" mass="7"/>

                    <body name="right_knee">
                        <geom name="right_knee_geom" size="0.1" type="sphere" pos="0 -0.15 -0.8" mass="0.5"/>

                        <body name="right_shin">
                            <joint axis="0 1 0" name="right_knee_to_right_shin" pos="0 0 -0.8" limited="true" range="0 90" type="hinge"/>
                            <geom name="right_shin_geom" fromto="0 -0.15 -0.9 0 -0.15 -1.2" size="0.05" type="capsule" mass="5"/>

                            <body name="right_ankle">
                                <geom name="right_ankle_geom" size="0.1" type="sphere" pos="0 -0.15 -1.2" mass="0.5"/>

                                <body name="right_foot">
                                    <joint axis="0 1 0" name="right_ankle_to_right_foot" pos="0 0 -1.2" limited="true" range="-15 90" type="hinge"/>
                                    <geom name="right_foot_geom" pos="0.15 -0.15 -1.2" size="0.15 0.05 0.075" type="box" mass="1"/>
                                </body>
                            </body>
                        </body>
                    </body>
                </body>
            </body>
            <!-- Beginning of left leg -->
            <body name="left_hip">
                <geom name="left_hip_geom" size="0.1" type="sphere" pos="0 0.15 -0.4" mass="0.5"/>
                <body name="left_thigh">
                    <joint axis="0 1 0" name="left_hip_to_left_thigh" pos="0 0.15 -0.4" limited="true" range="-90 90" type="hinge"/>
                    <geom name="left_thigh_geom" fromto="0 0.15 -0.5 0 0.15 -0.8" size="0.05" type="capsule" mass="7"/>

                    <body name="left_knee">
                        <geom name="left_knee_geom" size="0.1" type="sphere" pos="0 0.15 -0.8" mass="0.5"/>

                        <body name="left_shin">
                            <joint axis="0 1 0" name="left_thigh_to_left_shin" pos="0 0 -0.8" limited="true" range="0 90" type="hinge"/>
                            <geom name="left_shin_geom" fromto="0 0.15 -0.9 0 0.15 -1.2" size="0.05" type="capsule" mass="5"/>

                            <body name="left_ankle">
                                <geom name="left_ankle_geom" size="0.1" type="sphere" pos="0 0.15 -1.2" mass="0.5"/>

                                <body name="left_foot">
                                    <joint axis="0 1 0" name="left_ankle_to_left_foot" pos="0 0 -1.2" limited="true" range="-15 90" type="hinge"/>
                                    <geom name="left_foot_geom" pos="0.15 0.15 -1.2" size="0.15 0.05 0.075" type="box" mass="1"/>
                                </body>
                            </body>
                        </body>
                    </body>
                </body>
            </body>
        </body>
    </worldbody>
</mujoco>
